<?xml version="1.0" encoding="utf-8"?>
<!-- This URDF was automatically created by SolidWorks to URDF Exporter! Originally created by Stephen Brawner (brawner@gmail.com) 
     Commit Version: 1.6.0-4-g7f85cfe  Build Version: 1.6.7995.38578
     For more information, please see http://wiki.ros.org/sw_urdf_exporter -->
<robot
  name="transcent_urdf">
  <link
    name="base_link">
    <inertial>
      <origin
        xyz="0.027128 -0.0010297 -0.43674"
        rpy="0 0 0" />
      <mass
        value="25" />
      <inertia
        ixx="9.945"
        ixy="-0.072771"
        ixz="0.92751"
        iyy="8.4779"
        iyz="0.10811"
        izz="1.9417" />
    </inertial>
    <visual>
      <origin
        xyz="0 0 0"
        rpy="0 0 0" />
      <geometry>
        <mesh
          filename="package://urdf-rviz/Meshes/base_link.STL" />
      </geometry>
      <material
        name="">
        <color
          rgba="0.19216 0.41961 0.63333 1" />
      </material>
    </visual>
    <collision>
      <origin
        xyz="0 0 0"
        rpy="0 0 0" />
      <geometry>
        <mesh
          filename="package://urdf-rviz/Meshes/base_link.STL" />
      </geometry>
    </collision>
  </link>
  <link
    name="r_arm_sh_p1">
    <inertial>
      <origin
        xyz="0.43674 0.027128 -0.25094"
        rpy="0 0 0" />
      <mass
        value="2" />
      <inertia
        ixx="1.9413"
        ixy="-0.92765"
        ixz="0.095919"
        iyy="9.945"
        iyz="0.071041"
        izz="8.4783" />
    </inertial>
    <visual>
      <origin
        xyz="0 0 0"
        rpy="0 0 0" />
      <geometry>
        <mesh
          filename="package://urdf-rviz/Meshes/r_arm_sh_p1.STL" />
      </geometry>
      <material
        name="">
        <color
          rgba="0.19216 0.21961 0.2 1" />
      </material>
    </visual>
    <collision>
      <origin
        xyz="0 0 0"
        rpy="0 0 0" />
      <geometry>
        <mesh
          filename="package://urdf-rviz/Meshes/r_arm_sh_p1.STL" />
      </geometry>
    </collision>
  </link>
  <joint
    name="r_arm_sh_p1"
    type="revolute">
    <origin
      xyz="0 -0.25279 -0.0004714"
      rpy="-3.1416 1.5689 1.5708" />
    <parent
      link="base_link" />
    <child
      link="r_arm_sh_p1" />
    <axis
      xyz="0 0 1" />
    <limit
      lower="-3.14"
      upper="3.14"
      effort="130"
      velocity="3.14" />
  </joint>
  <link
    name="r_arm_sh_r">
    <inertial>
      <origin
        xyz="-0.0045709 0.12988 -0.00049479"
        rpy="0 0 0" />
      <mass
        value="2" />
      <inertia
        ixx="0.00015989"
        ixy="4.4882E-06"
        ixz="-1.3481E-19"
        iyy="3.2519E-05"
        iyz="3.8307E-18"
        izz="0.00016005" />
    </inertial>
    <visual>
      <origin
        xyz="0 0 0"
        rpy="0 0 0" />
      <geometry>
        <mesh
          filename="package://urdf-rviz/Meshes/r_arm_sh_r.STL" />
      </geometry>
      <material
        name="">
        <color
          rgba="0.09216 0.81961 0.03333 1" />
      </material>
    </visual>
    <collision>
      <origin
        xyz="0 0 0"
        rpy="0 0 0" />
      <geometry>
        <mesh
          filename="package://urdf-rviz/Meshes/r_arm_sh_r.STL" />
      </geometry>
    </collision>
  </link>
  <joint
    name="r_arm_sh_r"
    type="revolute">
    <origin
      xyz="0 0 0"
      rpy="1.5595 1.5708 0" />
    <parent
      link="r_arm_sh_p1" />
    <child
      link="r_arm_sh_r" />
    <axis
      xyz="0 0 1" />
    <limit
      lower="-3.14"
      upper="3.14"
      effort="130"
      velocity="3.14" />
  </joint>
  <link
    name="r_arm_sh_p2">
    <inertial>
      <origin
        xyz="-0.0005817 -3.8858E-16 -0.051497"
        rpy="0 0 0" />
      <mass
        value="2" />
      <inertia
        ixx="1.0152E-10"
        ixy="-6.0963E-27"
        ixz="1.0802E-12"
        iyy="1.0151E-10"
        iyz="-2.0639E-25"
        izz="1.9714E-10" />
    </inertial>
    <visual>
      <origin
        xyz="0 0 0"
        rpy="0 0 0" />
      <geometry>
        <mesh
          filename="package://urdf-rviz/Meshes/r_arm_sh_p2.STL" />
      </geometry>
      <material
        name="">
        <color
          rgba="0.19216 0.21961 0.2 1" />
      </material>
    </visual>
    <collision>
      <origin
        xyz="0 0 0"
        rpy="0 0 0" />
      <geometry>
        <mesh
          filename="package://urdf-rviz/Meshes/r_arm_sh_p2.STL" />
      </geometry>
    </collision>
  </link>
  <joint
    name="r_arm_sh_p2"
    type="revolute">
    <origin
      xyz="0 0.2349 0"
      rpy="0 1.5595 1.606" />
    <parent
      link="r_arm_sh_r" />
    <child
      link="r_arm_sh_p2" />
    <axis
      xyz="0 0 1" />
    <limit
      lower="-3.14"
      upper="3.14"
      effort="130"
      velocity="3.14" />
  </joint>
  <link
    name="r_arm_el_y">
    <inertial>
      <origin
        xyz="0.046061 -0.19389 -0.26236"
        rpy="0 0 0" />
      <mass
        value="2" />
      <inertia
        ixx="9.9573"
        ixy="0.70999"
        ixz="0.25073"
        iyy="1.9061"
        iyz="-0.24158"
        izz="8.5011" />
    </inertial>
    <visual>
      <origin
        xyz="0 0 0"
        rpy="0 0 0" />
      <geometry>
        <mesh
          filename="package://urdf-rviz/Meshes/r_arm_el_y.STL" />
      </geometry>
      <material
        name="">
        <color
          rgba="0.79216 0.11961 0.13333 1" />
      </material>
    </visual>
    <collision>
      <origin
        xyz="0 0 0"
        rpy="0 0 0" />
      <geometry>
        <mesh
          filename="package://urdf-rviz/Meshes/r_arm_el_y.STL" />
      </geometry>
    </collision>
  </link>
  <joint
    name="r_arm_el_y"
    type="revolute">
    <origin
      xyz="0 0 0"
      rpy="-1.572 0.030435 -0.10619" />
    <parent
      link="r_arm_sh_p2" />
    <child
      link="r_arm_el_y" />
    <axis
      xyz="0 0 1" />
    <limit
      lower="-3.14"
      upper="3.14"
      effort="130"
      velocity="3.14" />
  </joint>
  <link
    name="r_arm_wr_r">
    <inertial>
      <origin
        xyz="0.046061 -0.26236 -0.014498"
        rpy="0 0 0" />
      <mass
        value="2" />
      <inertia
        ixx="9.9573"
        ixy="0.25073"
        ixz="-0.70999"
        iyy="8.5011"
        iyz="0.24158"
        izz="1.9061" />
    </inertial>
    <visual>
      <origin
        xyz="0 0 0"
        rpy="0 0 0" />
      <geometry>
        <mesh
          filename="package://urdf-rviz/Meshes/r_arm_wr_r.STL" />
      </geometry>
      <material
        name="">
        <color
          rgba="0.39216 0.31961 0.33333 1" />
      </material>
    </visual>
    <collision>
      <origin
        xyz="0 0 0"
        rpy="0 0 0" />
      <geometry>
        <mesh
          filename="package://urdf-rviz/Meshes/r_arm_wr_r.STL" />
      </geometry>
    </collision>
  </link>
  <joint
    name="r_arm_wr_r"
    type="revolute">
    <origin
      xyz="0 -0.20839 0"
      rpy="1.5708 0 0" />
    <parent
      link="r_arm_el_y" />
    <child
      link="r_arm_wr_r" />
    <axis
      xyz="0 0 1" />
    <limit
      lower="-3.14"
      upper="3.14"
      effort="100"
      velocity="3.14" />
  </joint>
  <link
    name="r_arm_wr_y">
    <inertial>
      <origin
        xyz="0.064521 -0.014498 0.25844"
        rpy="0 0 0" />
      <mass
        value="2" />
      <inertia
        ixx="9.9146"
        ixy="-0.72531"
        ixz="-0.35106"
        iyy="1.9061"
        iyz="-0.19071"
        izz="8.5439" />
    </inertial>
    <visual>
      <origin
        xyz="0 0 0"
        rpy="0 0 0" />
      <geometry>
        <mesh
          filename="package://urdf-rviz/Meshes/r_arm_wr_y.STL" />
      </geometry>
      <material
        name="">
        <color
          rgba="0.09216 0.81961 0.03333 1" />
      </material>
    </visual>
    <collision>
      <origin
        xyz="0 0 0"
        rpy="0 0 0" />
      <geometry>
        <mesh
          filename="package://urdf-rviz/Meshes/r_arm_wr_y.STL" />
      </geometry>
    </collision>
  </link>
  <joint
    name="r_arm_wr_y"
    type="revolute">
    <origin
      xyz="0 0 0"
      rpy="1.5708 0 -0.07086" />
    <parent
      link="r_arm_wr_r" />
    <child
      link="r_arm_wr_y" />
    <axis
      xyz="0 0 1" />
    <limit
      lower="-3.14"
      upper="3.14"
      effort="100"
      velocity="3.14" />
  </joint>
  <link
    name="r_arm_wr_p">
    <inertial>
      <origin
        xyz="0.0035633 -0.002378 0.048742"
        rpy="0 0 0" />
      <mass
        value="2" />
      <inertia
        ixx="4.811E-05"
        ixy="3.5387E-07"
        ixz="-9.2205E-06"
        iyy="5.5016E-05"
        iyz="4.2427E-07"
        izz="3.921E-05" />
    </inertial>
    <visual>
      <origin
        xyz="0 0 0"
        rpy="0 0 0" />
      <geometry>
        <mesh
          filename="package://urdf-rviz/Meshes/r_arm_wr_p.STL" />
      </geometry>
      <material
        name="">
        <color
          rgba="0.79216 0.81961 0.33333 1" />
      </material>
    </visual>
    <collision>
      <origin
        xyz="0 0 0"
        rpy="0 0 0" />
      <geometry>
        <mesh
          filename="package://urdf-rviz/Meshes/r_arm_wr_p.STL" />
      </geometry>
    </collision>
  </link>
  <joint
    name="r_arm_wr_p"
    type="revolute">
    <origin
      xyz="0 0.10313 0"
      rpy="-1.5708 1.5708 0" />
    <parent
      link="r_arm_wr_y" />
    <child
      link="r_arm_wr_p" />
    <axis
      xyz="0 0 1" />
    <limit
      lower="-3.14"
      upper="3.14"
      effort="100"
      velocity="3.14" />
  </joint>
  <link
    name="r_arm_grip_thumb">
    <inertial>
      <origin
        xyz="0.038901 0.0041333 -0.020268"
        rpy="0 0 0" />
      <mass
        value="0.041233" />
      <inertia
        ixx="1.3497E-05"
        ixy="-1.5654E-07"
        ixz="4.94E-12"
        iyy="9.4283E-06"
        iyz="4.7406E-12"
        izz="1.0709E-05" />
    </inertial>
    <visual>
      <origin
        xyz="0 0 0"
        rpy="0 0 0" />
      <geometry>
        <mesh
          filename="package://urdf-rviz/Meshes/r_arm_grip_thumb.STL" />
      </geometry>
      <material
        name="">
        <color
          rgba="0.79216 0.81961 0.33333 1" />
      </material>
    </visual>
    <collision>
      <origin
        xyz="0 0 0"
        rpy="0 0 0" />
      <geometry>
        <mesh
          filename="package://urdf-rviz/Meshes/r_arm_grip_thumb.STL" />
      </geometry>
    </collision>
  </link>
  <joint
    name="r_arm_grip_thumb"
    type="revolute">
    <origin
      xyz="-0.03209 -0.046313 0.061228"
      rpy="-1.5708 -0.79395 3.0953" />
    <parent
      link="r_arm_wr_p" />
    <child
      link="r_arm_grip_thumb" />
    <axis
      xyz="0 0 1" />
    <limit
      lower="-3.14"
      upper="3.14"
      effort="3.7"
      velocity="6.28" />
  </joint>
  <link
    name="r_arm_grip_index">
    <inertial>
      <origin
        xyz="0.021582 0.039055 -0.020254"
        rpy="0 0 0" />
      <mass
        value="0.037783" />
      <inertia
        ixx="9.6946E-06"
        ixy="-9.7444E-07"
        ixz="-1.2257E-10"
        iyy="7.99E-06"
        iyz="-1.3078E-10"
        izz="5.663E-06" />
    </inertial>
    <visual>
      <origin
        xyz="0 0 0"
        rpy="0 0 0" />
      <geometry>
        <mesh
          filename="package://urdf-rviz/Meshes/r_arm_grip_index.STL" />
      </geometry>
      <material
        name="">
        <color
          rgba="0.79216 0.81961 0.33333 1" />
      </material>
    </visual>
    <collision>
      <origin
        xyz="0 0 0"
        rpy="0 0 0" />
      <geometry>
        <mesh
          filename="package://urdf-rviz/Meshes/r_arm_grip_index.STL" />
      </geometry>
    </collision>
  </link>
  <joint
    name="r_arm_grip_index"
    type="revolute">
    <origin
      xyz="0.024624 -0.048943 0.088022"
      rpy="1.5708 -0.7854 -0.046338" />
    <parent
      link="r_arm_wr_p" />
    <child
      link="r_arm_grip_index" />
    <axis
      xyz="0 0 1" />
    <limit
      lower="-3.14"
      upper="3.14"
      effort="3.7"
      velocity="6.28" />
  </joint>
  <link
    name="r_arm_grip_middle">
    <inertial>
      <origin
        xyz="0.032022 -0.0299 -0.02025"
        rpy="0 0 0" />
      <mass
        value="0.03778" />
      <inertia
        ixx="8.6084E-06"
        ixy="8.0918E-07"
        ixz="2.2221E-10"
        iyy="9.0699E-06"
        iyz="-1.034E-10"
        izz="5.6573E-06" />
    </inertial>
    <visual>
      <origin
        xyz="0 0 0"
        rpy="0 0 0" />
      <geometry>
        <mesh
          filename="package://urdf-rviz/Meshes/r_arm_grip_middle.STL" />
      </geometry>
      <material
        name="">
        <color
          rgba="0.79216 0.81961 0.33333 1" />
      </material>
    </visual>
    <collision>
      <origin
        xyz="0 0 0"
        rpy="0 0 0" />
      <geometry>
        <mesh
          filename="package://urdf-rviz/Meshes/r_arm_grip_middle.STL" />
      </geometry>
    </collision>
  </link>
  <joint
    name="r_arm_grip_middle"
    type="revolute">
    <origin
      xyz="0.029001 0.045455 0.088022"
      rpy="-1.5708 -0.7854 -0.046338" />
    <parent
      link="r_arm_wr_p" />
    <child
      link="r_arm_grip_middle" />
    <axis
      xyz="0 0 1" />
    <limit
      lower="-3.14"
      upper="3.14"
      effort="3.7"
      velocity="6.28" />
  </joint>
  <link
    name="l_arm_sh_p1">
    <inertial>
      <origin
        xyz="0.43674 -0.027128 -0.25506"
        rpy="0 0 0" />
      <mass
        value="2" />
      <inertia
        ixx="1.9413"
        ixy="0.92765"
        ixz="-0.095919"
        iyy="9.945"
        iyz="0.071041"
        izz="8.4783" />
    </inertial>
    <visual>
      <origin
        xyz="0 0 0"
        rpy="0 0 0" />
      <geometry>
        <mesh
          filename="package://urdf-rviz/Meshes/l_arm_sh_p1.STL" />
      </geometry>
      <material
        name="">
        <color
          rgba="0.19216 0.21961 0.2 1" />
      </material>
    </visual>
    <collision>
      <origin
        xyz="0 0 0"
        rpy="0 0 0" />
      <geometry>
        <mesh
          filename="package://urdf-rviz/Meshes/l_arm_sh_p1.STL" />
      </geometry>
    </collision>
  </link>
  <joint
    name="l_arm_sh_p1"
    type="revolute">
    <origin
      xyz="0 0.25321 0.0004722"
      rpy="0 1.5689 1.5708" />
    <parent
      link="base_link" />
    <child
      link="l_arm_sh_p1" />
    <axis
      xyz="0 0 1" />
    <limit
      lower="-3.14"
      upper="3.14"
      effort="130"
      velocity="3.14" />
  </joint>
  <link
    name="l_arm_sh_r">
    <inertial>
      <origin
        xyz="0.0045886 -0.12991 -0.00049641"
        rpy="0 0 0" />
      <mass
        value="2" />
      <inertia
        ixx="0.00024281"
        ixy="6.1705E-06"
        ixz="-2.2301E-19"
        iyy="6.833E-05"
        iyz="6.3619E-18"
        izz="0.00024302" />
    </inertial>
    <visual>
      <origin
        xyz="0 0 0"
        rpy="0 0 0" />
      <geometry>
        <mesh
          filename="package://urdf-rviz/Meshes/l_arm_sh_r.STL" />
      </geometry>
      <material
        name="">
        <color
          rgba="0.09216 0.81961 0.03333 1" />
      </material>
    </visual>
    <collision>
      <origin
        xyz="0 0 0"
        rpy="0 0 0" />
      <geometry>
        <mesh
          filename="package://urdf-rviz/Meshes/l_arm_sh_r.STL" />
      </geometry>
    </collision>
  </link>
  <joint
    name="l_arm_sh_r"
    type="revolute">
    <origin
      xyz="0 0 0"
      rpy="-1.5708 1.5708 0" />
    <parent
      link="l_arm_sh_p1" />
    <child
      link="l_arm_sh_r" />
    <axis
      xyz="0 0 1" />
    <limit
      lower="-3.14"
      upper="3.14"
      effort="130"
      velocity="3.14" />
  </joint>
  <link
    name="l_arm_sh_p2">
    <inertial>
      <origin
        xyz="-1.3509E-16 -5.5511E-17 -0.05105"
        rpy="0 0 0" />
      <mass
        value="2" />
      <inertia
        ixx="9.8605E-12"
        ixy="6.0644E-28"
        ixz="8.6901E-27"
        iyy="9.8605E-12"
        iyz="-2.8273E-27"
        izz="1.9715E-11" />
    </inertial>
    <visual>
      <origin
        xyz="0 0 0"
        rpy="0 0 0" />
      <geometry>
        <mesh
          filename="package://urdf-rviz/Meshes/l_arm_sh_p2.STL" />
      </geometry>
      <material
        name="">
        <color
          rgba="0.19216 0.21961 0.2 1" />
      </material>
    </visual>
    <collision>
      <origin
        xyz="0 0 0"
        rpy="0 0 0" />
      <geometry>
        <mesh
          filename="package://urdf-rviz/Meshes/l_arm_sh_p2.STL" />
      </geometry>
    </collision>
  </link>
  <joint
    name="l_arm_sh_p2"
    type="revolute">
    <origin
      xyz="0.0082954 -0.23485 -0.0005"
      rpy="0.01473 1.5708 -1.5208" />
    <parent
      link="l_arm_sh_r" />
    <child
      link="l_arm_sh_p2" />
    <axis
      xyz="0 0 1" />
    <limit
      lower="-3.14"
      upper="3.14"
      effort="130"
      velocity="3.14" />
  </joint>
  <link
    name="l_arm_el_y">
    <inertial>
      <origin
        xyz="0.005053 0.21103 -0.24071"
        rpy="0 0 0" />
      <mass
        value="2" />
      <inertia
        ixx="10.015"
        ixy="-0.4586"
        ixz="-0.15689"
        iyy="1.8726"
        iyz="-0.28811"
        izz="8.477" />
    </inertial>
    <visual>
      <origin
        xyz="0 0 0"
        rpy="0 0 0" />
      <geometry>
        <mesh
          filename="package://urdf-rviz/Meshes/l_arm_el_y.STL" />
      </geometry>
      <material
        name="">
        <color
          rgba="0.79216 0.11961 0.13333 1" />
      </material>
    </visual>
    <collision>
      <origin
        xyz="0 0 0"
        rpy="0 0 0" />
      <geometry>
        <mesh
          filename="package://urdf-rviz/Meshes/l_arm_el_y.STL" />
      </geometry>
    </collision>
  </link>
  <joint
    name="l_arm_el_y"
    type="revolute">
    <origin
      xyz="0 0 0"
      rpy="1.5708 0.070191 -0.047606" />
    <parent
      link="l_arm_sh_p2" />
    <child
      link="l_arm_el_y" />
    <axis
      xyz="0 0 1" />
    <limit
      lower="-3.14"
      upper="3.14"
      effort="130"
      velocity="3.14" />
  </joint>
  <link
    name="l_arm_wr_r">
    <inertial>
      <origin
        xyz="0.005053 0.24071 0.0026416"
        rpy="0 0 0" />
      <mass
        value="2" />
      <inertia
        ixx="10.015"
        ixy="0.15689"
        ixz="-0.4586"
        iyy="8.477"
        iyz="0.28811"
        izz="1.8726" />
    </inertial>
    <visual>
      <origin
        xyz="0 0 0"
        rpy="0 0 0" />
      <geometry>
        <mesh
          filename="package://urdf-rviz/Meshes/l_arm_wr_r.STL" />
      </geometry>
      <material
        name="">
        <color
          rgba="0.39216 0.31961 0.33333 1" />
      </material>
    </visual>
    <collision>
      <origin
        xyz="0 0 0"
        rpy="0 0 0" />
      <geometry>
        <mesh
          filename="package://urdf-rviz/Meshes/l_arm_wr_r.STL" />
      </geometry>
    </collision>
  </link>
  <joint
    name="l_arm_wr_r"
    type="revolute">
    <origin
      xyz="0 0.20839 0"
      rpy="-1.5708 0 0" />
    <parent
      link="l_arm_el_y" />
    <child
      link="l_arm_wr_r" />
    <axis
      xyz="0 0 1" />
    <limit
      lower="-3.14"
      upper="3.14"
      effort="100"
      velocity="3.14" />
  </joint>
  <link
    name="l_arm_wr_y">
    <inertial>
      <origin
        xyz="-0.0085486 -0.0026416 0.24061"
        rpy="0 0 0" />
      <mass
        value="2" />
      <inertia
        ixx="9.9924"
        ixy="0.47414"
        ixz="0.24261"
        iyy="1.8726"
        iyz="-0.26175"
        izz="8.4996" />
    </inertial>
    <visual>
      <origin
        xyz="0 0 0"
        rpy="0 0 0" />
      <geometry>
        <mesh
          filename="package://urdf-rviz/Meshes/l_arm_wr_y.STL" />
      </geometry>
      <material
        name="">
        <color
          rgba="0.09216 0.81961 0.03333 1" />
      </material>
    </visual>
    <collision>
      <origin
        xyz="0 0 0"
        rpy="0 0 0" />
      <geometry>
        <mesh
          filename="package://urdf-rviz/Meshes/l_arm_wr_y.STL" />
      </geometry>
    </collision>
  </link>
  <joint
    name="l_arm_wr_y"
    type="revolute">
    <origin
      xyz="0 0 0"
      rpy="-1.5708 0 -0.056502" />
    <parent
      link="l_arm_wr_r" />
    <child
      link="l_arm_wr_y" />
    <axis
      xyz="0 0 1" />
    <limit
      lower="-3.14"
      upper="3.14"
      effort="100"
      velocity="3.14" />
  </joint>
  <link
    name="l_arm_wr_p">
    <inertial>
      <origin
        xyz="-0.0038604 0.00024323 0.048771"
        rpy="0 0 0" />
      <mass
        value="2" />
      <inertia
        ixx="4.8842E-05"
        ixy="2.1539E-06"
        ixz="8.7332E-06"
        iyy="5.4285E-05"
        iyz="-2.988E-06"
        izz="3.9211E-05" />
    </inertial>
    <visual>
      <origin
        xyz="0 0 0"
        rpy="0 0 0" />
      <geometry>
        <mesh
          filename="package://urdf-rviz/Meshes/l_arm_wr_p.STL" />
      </geometry>
      <material
        name="">
        <color
          rgba="0.79216 0.81961 0.33333 1" />
      </material>
    </visual>
    <collision>
      <origin
        xyz="0 0 0"
        rpy="0 0 0" />
      <geometry>
        <mesh
          filename="package://urdf-rviz/Meshes/l_arm_wr_p.STL" />
      </geometry>
    </collision>
  </link>
  <joint
    name="l_arm_wr_p"
    type="revolute">
    <origin
      xyz="-0.0023782 -0.10317 0"
      rpy="2.9333 -1.5708 -1.3855" />
    <parent
      link="l_arm_wr_y" />
    <child
      link="l_arm_wr_p" />
    <axis
      xyz="0 0 1" />
    <limit
      lower="-3.14"
      upper="3.14"
      effort="100"
      velocity="3.14" />
  </joint>
  <link
    name="l_arm_grip_thumb">
    <inertial>
      <origin
        xyz="0.038624 -0.0062103 -0.020232"
        rpy="0 0 0" />
      <mass
        value="0.041233" />
      <inertia
        ixx="1.3502E-05"
        ixy="-6.1929E-08"
        ixz="-4.7664E-12"
        iyy="9.4231E-06"
        iyz="4.9647E-12"
        izz="1.0709E-05" />
    </inertial>
    <visual>
      <origin
        xyz="0 0 0"
        rpy="0 0 0" />
      <geometry>
        <mesh
          filename="package://urdf-rviz/Meshes/l_arm_grip_thumb.STL" />
      </geometry>
      <material
        name="">
        <color
          rgba="0.79216 0.81961 0.33333 1" />
      </material>
    </visual>
    <collision>
      <origin
        xyz="0 0 0"
        rpy="0 0 0" />
      <geometry>
        <mesh
          filename="package://urdf-rviz/Meshes/l_arm_grip_thumb.STL" />
      </geometry>
    </collision>
  </link>
  <joint
    name="l_arm_grip_thumb"
    type="revolute">
    <origin
      xyz="0.013423 -0.052958 0.061228"
      rpy="1.5708 -0.79395 -0.33001" />
    <parent
      link="l_arm_wr_p" />
    <child
      link="l_arm_grip_thumb" />
    <axis
      xyz="0 0 1" />
    <limit
      lower="-3.14"
      upper="3.14"
      effort="3.7"
      velocity="6.28" />
  </joint>
  <link
    name="l_arm_grip_index">
    <inertial>
      <origin
        xyz="0.031429 -0.031684 -0.020246"
        rpy="0 0 0" />
      <mass
        value="0.03778" />
      <inertia
        ixx="9.0537E-06"
        ixy="1.2725E-06"
        ixz="1.97E-10"
        iyy="8.6246E-06"
        iyz="-1.1685E-10"
        izz="5.6573E-06" />
    </inertial>
    <visual>
      <origin
        xyz="0 0 0"
        rpy="0 0 0" />
      <geometry>
        <mesh
          filename="package://urdf-rviz/Meshes/l_arm_grip_index.STL" />
      </geometry>
      <material
        name="">
        <color
          rgba="0.79216 0.81961 0.33333 1" />
      </material>
    </visual>
    <collision>
      <origin
        xyz="0 0 0"
        rpy="0 0 0" />
      <geometry>
        <mesh
          filename="package://urdf-rviz/Meshes/l_arm_grip_index.STL" />
      </geometry>
    </collision>
  </link>
  <joint
    name="l_arm_grip_index"
    type="revolute">
    <origin
      xyz="-0.040612 -0.035505 0.088022"
      rpy="-1.5708 -0.7854 2.8116" />
    <parent
      link="l_arm_wr_p" />
    <child
      link="l_arm_grip_index" />
    <axis
      xyz="0 0 1" />
    <limit
      lower="-3.14"
      upper="3.14"
      effort="3.7"
      velocity="6.28" />
  </joint>
  <link
    name="l_arm_grip_middle">
    <inertial>
      <origin
        xyz="0.033722 0.027968 -0.02025"
        rpy="0 0 0" />
      <mass
        value="0.037779" />
      <inertia
        ixx="8.515E-06"
        ixy="-7.7654E-07"
        ixz="-2.2558E-10"
        iyy="9.163E-06"
        iyz="-7.868E-11"
        izz="5.6572E-06" />
    </inertial>
    <visual>
      <origin
        xyz="0 0 0"
        rpy="0 0 0" />
      <geometry>
        <mesh
          filename="package://urdf-rviz/Meshes/l_arm_grip_middle.STL" />
      </geometry>
      <material
        name="">
        <color
          rgba="0.79216 0.81961 0.33333 1" />
      </material>
    </visual>
    <collision>
      <origin
        xyz="0 0 0"
        rpy="0 0 0" />
      <geometry>
        <mesh
          filename="package://urdf-rviz/Meshes/l_arm_grip_middle.STL" />
      </geometry>
    </collision>
  </link>
  <joint
    name="l_arm_grip_middle"
    type="revolute">
    <origin
      xyz="-0.0099887 0.053895 0.088022"
      rpy="1.5708 -0.7854 2.8116" />
    <parent
      link="l_arm_wr_p" />
    <child
      link="l_arm_grip_middle" />
    <axis
      xyz="0 0 1" />
    <limit
      lower="-3.14"
      upper="3.14"
      effort="3.7"
      velocity="6.28" />
  </joint>
  <link
    name="head_y">
    <inertial>
      <origin
        xyz="0.027128 -0.0010297 -0.43674"
        rpy="0 0 0" />
      <mass
        value="0.2" />
      <inertia
        ixx="9.945"
        ixy="-0.072771"
        ixz="0.92751"
        iyy="8.4779"
        iyz="0.10811"
        izz="1.9417" />
    </inertial>
    <visual>
      <origin
        xyz="0 0 0"
        rpy="0 0 0" />
      <geometry>
        <mesh
          filename="package://urdf-rviz/Meshes/head_y.STL" />
      </geometry>
      <material
        name="">
        <color
          rgba="0.79216 0.81961 0.93333 1" />
      </material>
    </visual>
    <collision>
      <origin
        xyz="0 0 0"
        rpy="0 0 0" />
      <geometry>
        <mesh
          filename="package://urdf-rviz/Meshes/head_y.STL" />
      </geometry>
    </collision>
  </link>
  <joint
    name="head_y"
    type="revolute">
    <origin
      xyz="0 0 0"
      rpy="0 0 0" />
    <parent
      link="base_link" />
    <child
      link="head_y" />
    <axis
      xyz="0 0 1" />
    <limit
      lower="-3.14"
      upper="3.14"
      effort="100"
      velocity="3.14" />
  </joint>
  <link
    name="head_p">
    <inertial>
      <origin
        xyz="0.006934 -0.5383 0.0010297"
        rpy="0 0 0" />
      <mass
        value="3" />
      <inertia
        ixx="10.003"
        ixy="0.62481"
        ixz="0.068663"
        iyy="1.8834"
        iyz="-0.11076"
        izz="8.4779" />
    </inertial>
    <visual>
      <origin
        xyz="0 0 0"
        rpy="0 0 0" />
      <geometry>
        <mesh
          filename="package://urdf-rviz/Meshes/head_p.STL" />
      </geometry>
      <material
        name="">
        <color
          rgba="0.69216 0.71961 0.33333 1" />
      </material>
    </visual>
    <collision>
      <origin
        xyz="0 0 0"
        rpy="0 0 0" />
      <geometry>
        <mesh
          filename="package://urdf-rviz/Meshes/head_p.STL" />
      </geometry>
    </collision>
  </link>
  <joint
    name="head_p"
    type="revolute">
    <origin
      xyz="0 0 0.10092"
      rpy="1.5708 -0.037531 0" />
    <parent
      link="head_y" />
    <child
      link="head_p" />
    <axis
      xyz="0 0 1" />
    <limit
      lower="-1.7"
      upper="1.7"
      effort="100"
      velocity="3.14" />
  </joint>
  <link
    name="r_antenna">
    <inertial>
      <origin
        xyz="-0.075514 0.027445 0.024546"
        rpy="0 0 0" />
      <mass
        value="0.11901" />
      <inertia
        ixx="5.0504E-05"
        ixy="8.4061E-05"
        ixz="4.9628E-05"
        iyy="0.00030692"
        iyz="-1.5664E-05"
        izz="0.00033403" />
    </inertial>
    <visual>
      <origin
        xyz="0 0 0"
        rpy="0 0 0" />
      <geometry>
        <mesh
          filename="package://urdf-rviz/Meshes/r_antenna.STL" />
      </geometry>
      <material
        name="">
        <color
          rgba="1 1 1 1" />
      </material>
    </visual>
    <collision>
      <origin
        xyz="0 0 0"
        rpy="0 0 0" />
      <geometry>
        <mesh
          filename="package://urdf-rviz/Meshes/r_antenna.STL" />
      </geometry>
    </collision>
  </link>
  <joint
    name="r_antenna"
    type="revolute">
    <origin
      xyz="-0.040336 0.089423 0.072087"
      rpy="0 0 -0.7854" />
    <parent
      link="head_p" />
    <child
      link="r_antenna" />
    <axis
      xyz="0 0 1" />
    <limit
      lower="-3.14"
      upper="3.14"
      effort="1"
      velocity="3.14" />
  </joint>
  <link
    name="l_antenna">
    <inertial>
      <origin
        xyz="-0.076735 -0.023816 0.024546"
        rpy="0 0 0" />
      <mass
        value="0.11901" />
      <inertia
        ixx="4.3073E-05"
        ixy="-7.1449E-05"
        ixz="5.0317E-05"
        iyy="0.00031435"
        iyz="1.3277E-05"
        izz="0.00033403" />
    </inertial>
    <visual>
      <origin
        xyz="0 0 0"
        rpy="0 0 0" />
      <geometry>
        <mesh
          filename="package://urdf-rviz/Meshes/l_antenna.STL" />
      </geometry>
      <material
        name="">
        <color
          rgba="1 1 1 1" />
      </material>
    </visual>
    <collision>
      <origin
        xyz="0 0 0"
        rpy="0 0 0" />
      <geometry>
        <mesh
          filename="package://urdf-rviz/Meshes/l_antenna.STL" />
      </geometry>
    </collision>
  </link>
  <joint
    name="l_antenna"
    type="revolute">
    <origin
      xyz="-0.040294 0.089379 -0.072093"
      rpy="3.1416 0 -0.7854" />
    <parent
      link="head_p" />
    <child
      link="l_antenna" />
    <axis
      xyz="0 0 1" />
    <limit
      lower="-3.14"
      upper="3.14"
      effort="1"
      velocity="3.14" />
  </joint>
  <link
    name="torso_y">
    <inertial>
      <origin
        xyz="0.0020581 -0.027124 0.15283"
        rpy="0 0 0" />
      <mass
        value="2" />
      <inertia
        ixx="8.4783"
        ixy="-0.071041"
        ixz="0.095919"
        iyy="9.945"
        iyz="0.92765"
        izz="1.9413" />
    </inertial>
    <visual>
      <origin
        xyz="0 0 0"
        rpy="0 0 0" />
      <geometry>
        <mesh
          filename="package://urdf-rviz/Meshes/torso_y.STL" />
      </geometry>
      <material
        name="">
        <color
          rgba="0.29216 0.21961 0.2 1" />
      </material>
    </visual>
    <collision>
      <origin
        xyz="0 0 0"
        rpy="0 0 0" />
      <geometry>
        <mesh
          filename="package://urdf-rviz/Meshes/torso_y.STL" />
      </geometry>
    </collision>
  </link>
  <joint
    name="torso_y"
    type="revolute">
    <origin
      xyz="0 0.00074335 -0.28391"
      rpy="3.1416 0.0018648 -1.5708" />
    <parent
      link="base_link" />
    <child
      link="torso_y" />
    <axis
      xyz="0 0 1" />
    <limit
      lower="-3.14"
      upper="3.14"
      effort="130"
      velocity="3.14" />
  </joint>
  <link
    name="r_leg_hip_r">
    <inertial>
      <origin
        xyz="-0.081439 0.052424 0.027321"
        rpy="0 0 0" />
      <mass
        value="2" />
      <inertia
        ixx="8.4762"
        ixy="0.11291"
        ixz="0.044104"
        iyy="1.9413"
        iyz="-0.92573"
        izz="9.9471" />
    </inertial>
    <visual>
      <origin
        xyz="0 0 0"
        rpy="0 0 0" />
      <geometry>
        <mesh
          filename="package://urdf-rviz/Meshes/r_leg_hip_r.STL" />
      </geometry>
      <material
        name="">
        <color
          rgba="0.79216 0.11961 0.13333 1" />
      </material>
    </visual>
    <collision>
      <origin
        xyz="0 0 0"
        rpy="0 0 0" />
      <geometry>
        <mesh
          filename="package://urdf-rviz/Meshes/r_leg_hip_r.STL" />
      </geometry>
    </collision>
  </link>
  <joint
    name="r_leg_hip_r"
    type="revolute">
    <origin
      xyz="0.082983 0.0016863 0.10041"
      rpy="1.5708 0 0.018337" />
    <parent
      link="torso_y" />
    <child
      link="r_leg_hip_r" />
    <axis
      xyz="0 0 1" />
    <limit
      lower="-1.57"
      upper="1.57"
      effort="130"
      velocity="3.14" />
  </joint>
  <link
    name="r_leg_hip_y">
    <inertial>
      <origin
        xyz="-0.028695 0.081703 -0.029802"
        rpy="0 0 0" />
      <mass
        value="2" />
      <inertia
        ixx="9.9444"
        ixy="0.084983"
        ixz="0.92868"
        iyy="8.4739"
        iyz="-0.19373"
        izz="1.9462" />
    </inertial>
    <visual>
      <origin
        xyz="0 0 0"
        rpy="0 0 0" />
      <geometry>
        <mesh
          filename="package://urdf-rviz/Meshes/r_leg_hip_y.STL" />
      </geometry>
      <material
        name="">
        <color
          rgba="0.39216 0.31961 0.33333 1" />
      </material>
    </visual>
    <collision>
      <origin
        xyz="0 0 0"
        rpy="0 0 0" />
      <geometry>
        <mesh
          filename="package://urdf-rviz/Meshes/r_leg_hip_y.STL" />
      </geometry>
    </collision>
  </link>
  <joint
    name="r_leg_hip_y"
    type="revolute">
    <origin
      xyz="0.0012133 0.080991 0.00012943"
      rpy="-1.5708 1.5525 -0.014978" />
    <parent
      link="r_leg_hip_r" />
    <child
      link="r_leg_hip_y" />
    <axis
      xyz="0 0 1" />
    <limit
      lower="-3.14"
      upper="3.14"
      effort="130"
      velocity="3.14" />
  </joint>
  <link
    name="r_leg_hip_p">
    <inertial>
      <origin
        xyz="-0.091247 0.030399 -0.15513"
        rpy="0 0 0" />
      <mass
        value="3" />
      <inertia
        ixx="1.9462"
        ixy="-0.9325"
        ixz="0.17439"
        iyy="9.9403"
        iyz="0.11546"
        izz="8.4781" />
    </inertial>
    <visual>
      <origin
        xyz="0 0 0"
        rpy="0 0 0" />
      <geometry>
        <mesh
          filename="package://urdf-rviz/Meshes/r_leg_hip_p.STL" />
      </geometry>
      <material
        name="">
        <color
          rgba="0.79216 0.81961 0.93333 1" />
      </material>
    </visual>
    <collision>
      <origin
        xyz="0 0 0"
        rpy="0 0 0" />
      <geometry>
        <mesh
          filename="package://urdf-rviz/Meshes/r_leg_hip_p.STL" />
      </geometry>
    </collision>
  </link>
  <joint
    name="r_leg_hip_p"
    type="revolute">
    <origin
      xyz="-0.0015262 -0.07402 0.061445"
      rpy="-2.8161 -1.5708 -1.9173" />
    <parent
      link="r_leg_hip_y" />
    <child
      link="r_leg_hip_p" />
    <axis
      xyz="0 0 1" />
    <limit
      lower="-3.14"
      upper="3.14"
      effort="130"
      velocity="3.14" />
  </joint>
  <link
    name="r_leg_kn_p">
    <inertial>
      <origin
        xyz="-0.39616 0.061419 -0.15519"
        rpy="0 0 0" />
      <mass
        value="3" />
      <inertia
        ixx="2.3424"
        ixy="1.9706"
        ixz="0.19645"
        iyy="9.5434"
        iyz="0.049536"
        izz="8.4788" />
    </inertial>
    <visual>
      <origin
        xyz="0 0 0"
        rpy="0 0 0" />
      <geometry>
        <mesh
          filename="package://urdf-rviz/Meshes/r_leg_kn_p.STL" />
      </geometry>
      <material
        name="">
        <color
          rgba="0.79216 0.11961 0.33333 1" />
      </material>
    </visual>
    <collision>
      <origin
        xyz="0 0 0"
        rpy="0 0 0" />
      <geometry>
        <mesh
          filename="package://urdf-rviz/Meshes/r_leg_kn_p.STL" />
      </geometry>
    </collision>
  </link>
  <joint
    name="r_leg_kn_p"
    type="revolute">
    <origin
      xyz="0.30091 0.11466 -0.000492"
      rpy="-0.00086959 0.0015288 0.36503" />
    <parent
      link="r_leg_hip_p" />
    <child
      link="r_leg_kn_p" />
    <axis
      xyz="0 0 1" />
    <limit
      lower="-3.14"
      upper="3.14"
      effort="130"
      velocity="3.14" />
  </joint>
  <link
    name="r_leg_an_p">
    <inertial>
      <origin
        xyz="-0.72989 -0.15888 -0.15519"
        rpy="0 0 0" />
      <mass
        value="2" />
      <inertia
        ixx="2.1933"
        ixy="-1.6696"
        ixz="0.15406"
        iyy="9.6925"
        iyz="0.13158"
        izz="8.4788" />
    </inertial>
    <visual>
      <origin
        xyz="0 0 0"
        rpy="0 0 0" />
      <geometry>
        <mesh
          filename="package://urdf-rviz/Meshes/r_leg_an_p.STL" />
      </geometry>
      <material
        name="">
        <color
          rgba="0.79216 0.11961 0.13333 1" />
      </material>
    </visual>
    <collision>
      <origin
        xyz="0 0 0"
        rpy="0 0 0" />
      <geometry>
        <mesh
          filename="package://urdf-rviz/Meshes/r_leg_an_p.STL" />
      </geometry>
    </collision>
  </link>
  <joint
    name="r_leg_an_p"
    type="revolute">
    <origin
      xyz="0.32842 -0.12014 0"
      rpy="0 0 -0.45985" />
    <parent
      link="r_leg_kn_p" />
    <child
      link="r_leg_an_p" />
    <axis
      xyz="0 0 1" />
    <limit
      lower="-3.14"
      upper="3.14"
      effort="130"
      velocity="3.14" />
  </joint>
  <link
    name="r_leg_an_r">
    <inertial>
      <origin
        xyz="-0.80663 0.083038 -0.15886"
        rpy="0 0 0" />
      <mass
        value="2" />
      <inertia
        ixx="2.1933"
        ixy="-0.15406"
        ixz="-1.6696"
        iyy="8.4788"
        iyz="-0.13158"
        izz="9.6925" />
    </inertial>
    <visual>
      <origin
        xyz="0 0 0"
        rpy="0 0 0" />
      <geometry>
        <mesh
          filename="package://urdf-rviz/Meshes/r_leg_an_r.STL" />
      </geometry>
      <material
        name="">
        <color
          rgba="0.19216 0.11961 0.13333 1" />
      </material>
    </visual>
    <collision>
      <origin
        xyz="0 0 0"
        rpy="0 0 0" />
      <geometry>
        <mesh
          filename="package://urdf-rviz/Meshes/r_leg_an_r.STL" />
      </geometry>
    </collision>
  </link>
  <joint
    name="r_leg_an_r"
    type="revolute">
    <origin
      xyz="0.076746 -2.5E-05 -0.072148"
      rpy="-1.5708 0 0" />
    <parent
      link="r_leg_an_p" />
    <child
      link="r_leg_an_r" />
    <axis
      xyz="0 0 1" />
    <limit
      lower="-3.14"
      upper="3.14"
      effort="130"
      velocity="3.14" />
  </joint>
  <link
    name="l_leg_hip_r">
    <inertial>
      <origin
        xyz="0.08456 0.052424 0.027192"
        rpy="0 0 0" />
      <mass
        value="2" />
      <inertia
        ixx="8.4762"
        ixy="0.11291"
        ixz="0.044104"
        iyy="1.9413"
        iyz="-0.92573"
        izz="9.9471" />
    </inertial>
    <visual>
      <origin
        xyz="0 0 0"
        rpy="0 0 0" />
      <geometry>
        <mesh
          filename="package://urdf-rviz/Meshes/l_leg_hip_r.STL" />
      </geometry>
      <material
        name="">
        <color
          rgba="0.79216 0.11961 0.13333 1" />
      </material>
    </visual>
    <collision>
      <origin
        xyz="0 0 0"
        rpy="0 0 0" />
      <geometry>
        <mesh
          filename="package://urdf-rviz/Meshes/l_leg_hip_r.STL" />
      </geometry>
    </collision>
  </link>
  <joint
    name="l_leg_hip_r"
    type="revolute">
    <origin
      xyz="-0.082987 -0.0014869 0.10041"
      rpy="1.5708 0 0.018337" />
    <parent
      link="torso_y" />
    <child
      link="l_leg_hip_r" />
    <axis
      xyz="0 0 1" />
    <limit
      lower="-1.57"
      upper="1.57"
      effort="130"
      velocity="3.14" />
  </joint>
  <link
    name="l_leg_hip_y">
    <inertial>
      <origin
        xyz="0.027192 0.085691 -0.030505"
        rpy="0 0 0" />
      <mass
        value="2" />
      <inertia
        ixx="9.9471"
        ixy="0.023121"
        ixz="-0.92649"
        iyy="8.4779"
        iyz="-0.035209"
        izz="1.9396" />
    </inertial>
    <visual>
      <origin
        xyz="0 0 0"
        rpy="0 0 0" />
      <geometry>
        <mesh
          filename="package://urdf-rviz/Meshes/l_leg_hip_y.STL" />
      </geometry>
      <material
        name="">
        <color
          rgba="0.39216 0.31961 0.33333 1" />
      </material>
    </visual>
    <collision>
      <origin
        xyz="0 0 0"
        rpy="0 0 0" />
      <geometry>
        <mesh
          filename="package://urdf-rviz/Meshes/l_leg_hip_y.STL" />
      </geometry>
    </collision>
  </link>
  <joint
    name="l_leg_hip_y"
    type="revolute">
    <origin
      xyz="0.0012133 0.080991 0.00012943"
      rpy="-1.5708 -1.5708 0" />
    <parent
      link="l_leg_hip_r" />
    <child
      link="l_leg_hip_y" />
    <axis
      xyz="0 0 1" />
    <limit
      lower="-3.14"
      upper="3.14"
      effort="130"
      velocity="3.14" />
  </joint>
  <link
    name="l_leg_hip_p">
    <inertial>
      <origin
        xyz="-0.091948 -0.010406 -0.15786"
        rpy="0 0 0" />
      <mass
        value="3" />
      <inertia
        ixx="1.9402"
        ixy="0.90578"
        ixz="0.21021"
        iyy="9.8851"
        iyz="0.2947"
        izz="8.5393" />
    </inertial>
    <visual>
      <origin
        xyz="0 0 0"
        rpy="0 0 0" />
      <geometry>
        <mesh
          filename="package://urdf-rviz/Meshes/l_leg_hip_p.STL" />
      </geometry>
      <material
        name="">
        <color
          rgba="0.79216 0.81961 0.93333 1" />
      </material>
    </visual>
    <collision>
      <origin
        xyz="0 0 0"
        rpy="0 0 0" />
      <geometry>
        <mesh
          filename="package://urdf-rviz/Meshes/l_leg_hip_p.STL" />
      </geometry>
    </collision>
  </link>
  <joint
    name="l_leg_hip_p"
    type="revolute">
    <origin
      xyz="-0.012966 -0.067334 0.061439"
      rpy="-1.5708 -1.5705 2.951" />
    <parent
      link="l_leg_hip_y" />
    <child
      link="l_leg_hip_p" />
    <axis
      xyz="0 0 1" />
    <limit
      lower="-3.14"
      upper="3.14"
      effort="130"
      velocity="3.14" />
  </joint>
  <link
    name="l_leg_kn_p">
    <inertial>
      <origin
        xyz="-0.39831 -0.052316 -0.15798"
        rpy="0 0 0" />
      <mass
        value="3" />
      <inertia
        ixx="2.9344"
        ixy="-2.7807"
        ixz="0.040871"
        iyy="8.8896"
        iyz="0.35847"
        izz="8.5405" />
    </inertial>
    <visual>
      <origin
        xyz="0 0 0"
        rpy="0 0 0" />
      <geometry>
        <mesh
          filename="package://urdf-rviz/Meshes/l_leg_kn_p.STL" />
      </geometry>
      <material
        name="">
        <color
          rgba="0.79216 0.11961 0.13333 1" />
      </material>
    </visual>
    <collision>
      <origin
        xyz="0 0 0"
        rpy="0 0 0" />
      <geometry>
        <mesh
          filename="package://urdf-rviz/Meshes/l_leg_kn_p.STL" />
      </geometry>
    </collision>
  </link>
  <joint
    name="l_leg_kn_p"
    type="revolute">
    <origin
      xyz="0.28463 -0.1506 -0.00011379"
      rpy="-0.0017233 0.00035165 -0.48763" />
    <parent
      link="l_leg_hip_p" />
    <child
      link="l_leg_kn_p" />
    <axis
      xyz="0 0 1" />
    <limit
      lower="-3.14"
      upper="3.14"
      effort="130"
      velocity="3.14" />
  </joint>
  <link
    name="l_leg_an_p">
    <inertial>
      <origin
        xyz="-0.73696 0.069546 -0.15798"
        rpy="0 0 0" />
      <mass
        value="2" />
      <inertia
        ixx="1.8388"
        ixy="0.083566"
        ixz="0.17278"
        iyy="9.9853"
        iyz="0.31673"
        izz="8.5405" />
    </inertial>
    <visual>
      <origin
        xyz="0 0 0"
        rpy="0 0 0" />
      <geometry>
        <mesh
          filename="package://urdf-rviz/Meshes/l_leg_an_p.STL" />
      </geometry>
      <material
        name="">
        <color
          rgba="0.79216 0.11961 0.13333 1" />
      </material>
    </visual>
    <collision>
      <origin
        xyz="0 0 0"
        rpy="0 0 0" />
      <geometry>
        <mesh
          filename="package://urdf-rviz/Meshes/l_leg_an_p.STL" />
      </geometry>
    </collision>
  </link>
  <joint
    name="l_leg_an_p"
    type="revolute">
    <origin
      xyz="0.31064 0.16061 0"
      rpy="0 0 0.38586" />
    <parent
      link="l_leg_kn_p" />
    <child
      link="l_leg_an_p" />
    <axis
      xyz="0 0 1" />
    <limit
      lower="-3.14"
      upper="3.14"
      effort="130"
      velocity="3.14" />
  </joint>
  <link
    name="l_leg_an_r">
    <inertial>
      <origin
        xyz="-0.81361 -0.085978 -0.069571"
        rpy="0 0 0" />
      <mass
        value="2" />
      <inertia
        ixx="1.8388"
        ixy="0.17278"
        ixz="-0.083566"
        iyy="8.5405"
        iyz="-0.31673"
        izz="9.9853" />
    </inertial>
    <visual>
      <origin
        xyz="0 0 0"
        rpy="0 0 0" />
      <geometry>
        <mesh
          filename="package://urdf-rviz/Meshes/l_leg_an_r.STL" />
      </geometry>
      <material
        name="">
        <color
          rgba="0.19216 0.11961 0.13333 1" />
      </material>
    </visual>
    <collision>
      <origin
        xyz="0 0 0"
        rpy="0 0 0" />
      <geometry>
        <mesh
          filename="package://urdf-rviz/Meshes/l_leg_an_r.STL" />
      </geometry>
    </collision>
  </link>
  <joint
    name="l_leg_an_r"
    type="revolute">
    <origin
      xyz="0.07665 -2.5E-05 -0.072"
      rpy="1.5708 0 0" />
    <parent
      link="l_leg_an_p" />
    <child
      link="l_leg_an_r" />
    <axis
      xyz="0 0 1" />
    <limit
      lower="-3.14"
      upper="3.14"
      effort="130"
      velocity="3.14" />
  </joint>
</robot>