<?xml version="1.0" encoding="utf-8" ?>
<!-- This URDF was automatically created by SolidWorks to URDF Exporter! Originally created by Stephen Brawner (brawner@gmail.com) 
     Commit Version: 1.6.0-4-g7f85cfe  Build Version: 1.6.7995.38578
     For more information, please see http://wiki.ros.org/sw_urdf_exporter -->
<robot name="transcent_urdf">
    <!-- ****************************** COLORS ****************************** -->
    <material name="black">
        <color rgba="0.0 0.0 0.0 1.0" />
    </material>
    <material name="blue">
        <color rgba="0.0 1.0 1.0 1.0" />
    </material>
    <material name="green">
        <color rgba="0.0 0.8 0.0 1.0" />
    </material>
    <material name="grey">
        <color rgba="0.5 0.5 0.5 1.0" />
    </material>
    <material name="silver">
        <color rgba="0.79216 0.81961 0.93333 1" />
    </material>
    <material name="orange">
        <color rgba="0.9764705882352941 0.45098039215686275 0.023529411764705882 1.0" />
    </material>
    <material name="brown">
        <color rgba="0.396078431372549 0.21568627450980393 0.0 1.0" />
    </material>
    <material name="red">
        <color rgba="0.8 0.0 0.0 1.0" />
    </material>
    <material name="white">
        <color rgba="1.0 1.0 1.0 1.0" />
    </material>
    <material name="yellow">
        <color rgba="1.0 1.0 0.0 1.0" />
    </material>
    <material name="olive">
        <color rgba="0.4 0.4 0.2 1.0" />
    </material>
    <material name="light_blue">
        <color rgba="0.4 0.6 0.8 1.0" />
    </material>
    <material name="light_brown">
        <color rgba="0.6 0.4 0.2 1.0" />
    </material>
    <!-- ****************************** world ****************************** -->
    <link name="world" />

    <joint name="robot_to_world" type="fixed">
     <origin xyz="0.0 0.0 0.9" rpy="0.0 0.0 0" />
     <parent link="world" />
     <child link="base_link" />

    </joint>   

    <!-- ****************************** BASE ****************************** -->  
     <!-- link 2 -->  
    <link name="base_link">
        <inertial>
            <origin xyz="0.027128 -0.0010297 -0.43674" rpy="0 0 0" />
            <mass value="25" />
            <inertia ixx="1.0" ixy="0.0" ixz="0.0" iyy="1.0" iyz="0.0" izz="1.0" />
        </inertial>
        <visual>
            <origin xyz="0 0 0" rpy="0 0 0" />
            <geometry>
                <mesh filename="package://transcent_urdf/meshes/base_link.STL" />
            </geometry>
            <material name="light_blue" />
        </visual>
        <collision>
            <origin xyz="0 0 0" rpy="0 0 0" />
            <geometry>
                <mesh filename="package://transcent_urdf/meshes/base_link.STL" />
            </geometry>
        </collision>
    </link>
    <!--****************  Right Arm  ******************-->
     <!-- link 2 -->
    <link name="r_arm_sh_p1">
        <inertial>
            <origin xyz="0.43674 0.027128 -0.25094" rpy="0 0 0" />
            <mass value="0.85644" />
            <inertia ixx="1" ixy="0.0" ixz="0.0" iyy="1" iyz="0.0" izz="1" />
        </inertial>
        <visual>
            <origin xyz="0 0 0" rpy="0 0 0" />
            <geometry>
                <mesh filename="package://transcent_urdf/meshes/r_arm_sh_p1.STL" />
            </geometry>
            <material name="">
                <color rgba="0.19216 0.21961 0.2 1" />
            </material>
        </visual>
        <collision>
            <origin xyz="0 0 0" rpy="0 0 0" />
            <geometry>
                <mesh filename="package://transcent_urdf/meshes/r_arm_sh_p1.STL" />
            </geometry>
        </collision>
    </link>
    <!-- Joint 1 -->
    <joint name="r_arm_sh_p1_joint" type="revolute">
        <origin xyz="0 -0.25279 -0.0004714" rpy="-3.1416 1.5689 1.5708" />
        <parent link="base_link" />
        <child link="r_arm_sh_p1" />
        <axis xyz="0 0 1" />
        <limit lower="-1.57" upper="1.57" effort="130" velocity="3.14" />
        <dynamics damping="1.0" friction="0"/>
    </joint>
    <!-- Link3 -->
    <link name="r_arm_sh_r">
        <inertial>
            <origin xyz="-0.0045709 0.12988 -0.00049479" rpy="0 0 0" />
            <mass value="0.2" />
            <inertia ixx="1.0" ixy="0.0" ixz="0.0" iyy="1.0" iyz="0.0" izz="1.0" />
        </inertial>
        <visual>
            <origin xyz="0 0 0" rpy="0 0 0" />
            <geometry>
                <mesh filename="package://transcent_urdf/meshes/r_arm_sh_r.STL" />
            </geometry>
            <material name="">
                <color rgba="0.09216 0.81961 0.03333 1" />
            </material>
        </visual>
        <collision>
            <origin xyz="0 0 0" rpy="0 0 0" />
            <geometry>
                <mesh filename="package://transcent_urdf/meshes/r_arm_sh_r.STL" />
            </geometry>
        </collision>
    </link>
      <!-- Joint 2 -->
    <joint name="r_arm_sh_r_joint" type="revolute">
        <origin xyz="0 0 0" rpy="1.5595 1.5708 0" />
        <parent link="r_arm_sh_p1" />
        <child link="r_arm_sh_r" />
        <axis xyz="0 0 1" />
        <limit lower="0" upper="3.14" effort="130" velocity="3.14" />
        <dynamics damping="1.0" friction="0"/>
    </joint>
      <!-- Link4 -->
    <link name="r_arm_sh_p2">
        <inertial>
            <origin xyz="-0.0005817 -3.8858E-16 -0.051497" rpy="0 0 0" />
            <mass value="0.2" />
            <inertia ixx="1.0" ixy="0.0" ixz="0.0" iyy="1.0" iyz="0.0" izz="1.0" />
        </inertial>
        <visual>
            <origin xyz="0 0 0" rpy="0 0 0" />
            <geometry>
                <mesh filename="package://transcent_urdf/meshes/r_arm_sh_p2.STL" />
            </geometry>
            <material name="silver" />
        </visual>
        <collision>
            <origin xyz="0 0 0" rpy="0 0 0" />
            <geometry>
                <mesh filename="package://transcent_urdf/meshes/r_arm_sh_p2.STL" />
            </geometry>
        </collision>
    </link>
     <!-- Joint 3 -->
    <joint name="r_arm_sh_p2_joint" type="revolute">
        <origin xyz="0 0.2349 0" rpy="0 1.5595 1.606" />
        <parent link="r_arm_sh_r" />
        <child link="r_arm_sh_p2" />
        <axis xyz="0 0 1" />
        <limit lower="-2.1" upper="1.57" effort="130" velocity="3.14" />
        <dynamics damping="1.0" friction="0"/>
    </joint>
      <!-- Link5 -->
    <link name="r_arm_el_y">
        <inertial>
            <origin xyz="0.046061 -0.19389 -0.26236" rpy="0 0 0" />
            <mass value="0.2" />
            <inertia ixx="1.0" ixy="0.0" ixz="0.0" iyy="1.0" iyz="0.0" izz="1.0" />
        </inertial>
        <visual>
            <origin xyz="0 0 0" rpy="0 0 0" />
            <geometry>
                <mesh filename="package://transcent_urdf/meshes/r_arm_el_y.STL" />
            </geometry>
            <material name="">
                <color rgba="0.79216 0.11961 0.13333 1" />
            </material>
        </visual>
        <collision>
            <origin xyz="0 0 0" rpy="0 0 0" />
            <geometry>
                <mesh filename="package://transcent_urdf/meshes/r_arm_el_y.STL" />
            </geometry>
        </collision>
    </link>
      <!-- Joint 4 -->
    <joint name="r_arm_el_y_joint" type="revolute">
        <origin xyz="0 0 0" rpy="-1.572 0.030435 -0.10619" />
        <parent link="r_arm_sh_p2" />
        <child link="r_arm_el_y" />
        <axis xyz="0 0 1" />
        <limit lower="0" upper="2.1" effort="130" velocity="3.14" />
        <dynamics damping="1.0" friction="0"/>
    </joint>
  <!-- Link6 -->
    <link name="r_arm_wr_r">
        <inertial>
            <origin xyz="0.046061 -0.26236 -0.014498" rpy="0 0 0" />
            <mass value="0.2" />
            <inertia ixx="1.0" ixy="0.0" ixz="0.0" iyy="1.0" iyz="0.0" izz="1.0" />
        </inertial>
        <visual>
            <origin xyz="0 0 0" rpy="0 0 0" />
            <geometry>
                <mesh filename="package://transcent_urdf/meshes/r_arm_wr_r.STL" />
            </geometry>
            <material name="grey" />
        </visual>
        <collision>
            <origin xyz="0 0 0" rpy="0 0 0" />
            <geometry>
                <mesh filename="package://transcent_urdf/meshes/r_arm_wr_r.STL" />
            </geometry>
        </collision>
    </link>
     <!-- Joint 5 -->
    <joint name="r_arm_wr_r_joint" type="revolute">
        <origin xyz="0 -0.20839 0" rpy="1.5708 0 0" />
        <parent link="r_arm_el_y" />
        <child link="r_arm_wr_r" />
        <dynamics damping="0.1" friction="0"/>
        <axis xyz="0 0 1" />
        <limit lower="-1.57" upper="1.57" effort="100" velocity="3.14" />
        <dynamics damping="1.0" friction="0"/>
    </joint>
  <!-- end_link -->
    <link name="r_arm_wr_y">
        <inertial>
            <origin xyz="0.064521 -0.014498 0.25844" rpy="0 0 0" />
            <mass value="0.2" />
            <inertia ixx="1.0" ixy="0.0" ixz="0.0" iyy="1.0" iyz="0.0" izz="1.0" />
        </inertial>
        <visual>
            <origin xyz="0 0 0" rpy="0 0 0" />
            <geometry>
                <mesh filename="package://transcent_urdf/meshes/r_arm_wr_y.STL" />
            </geometry>
            <material name="">
                <color rgba="0.09216 0.81961 0.03333 1" />
            </material>
        </visual>
        <collision>
            <origin xyz="0 0 0" rpy="0 0 0" />
            <geometry>
                <mesh filename="package://transcent_urdf/meshes/r_arm_wr_y.STL" />
            </geometry>
        </collision>
    </link>
      <!-- Joint 6 -->
    <joint name="r_arm_wr_y_joint" type="revolute">
        <origin xyz="0 0 0" rpy="1.5708 0 -0.07086" />
        <parent link="r_arm_wr_r" />
        <child link="r_arm_wr_y" />
        <axis xyz="0 0 1" />
        <limit lower="-3.14" upper="3.14" effort="100" velocity="3.14" />
        <dynamics damping="1.0" friction="0"/>
    </joint>
    
    <link name="r_arm_wr_p">
        <inertial>
            <origin xyz="0.0035633 -0.002378 0.048742" rpy="0 0 0" />
            <mass value="0.2" />
            <inertia ixx="1.0" ixy="0.0" ixz="0.0" iyy="1.0" iyz="0.0" izz="1.0" />
        </inertial>
        <visual>
            <origin xyz="0 0 0" rpy="0 0 0" />
            <geometry>
                <mesh filename="package://transcent_urdf/meshes/r_arm_wr_p.STL" />
            </geometry>
            <material name="">
                <color rgba="0.79216 0.81961 0.33333 1" />
            </material>
        </visual>
        <collision>
            <origin xyz="0 0 0" rpy="0 0 0" />
            <geometry>
                <mesh filename="package://transcent_urdf/meshes/r_arm_wr_p.STL" />
            </geometry>
        </collision>
    </link>

      <!-- Joint 7 -->
    <joint name="r_arm_wr_p_joint" type="revolute">
        <origin xyz="0 0.10313 0" rpy="-1.5708 1.5708 0" />
        <parent link="r_arm_wr_y" />
        <child link="r_arm_wr_p" />
        <axis xyz="0 0 1" />
        <limit lower="-1.05" upper="1.05" effort="100" velocity="3.14" />
        <dynamics damping="1.0" friction="0"/>
    </joint>



    <link name="r_arm_grip_thumb">
        <inertial>
            <origin xyz="0.038901 0.0041333 -0.020268" rpy="0 0 0" />
            <mass value="0.041233" />
            <inertia ixx="1.0" ixy="0.0" ixz="0.0" iyy="1.0" iyz="0.0" izz="1.0" />
        </inertial>
        <visual>
            <origin xyz="0 0 0" rpy="0 0 0" />
            <geometry>
                <mesh filename="package://transcent_urdf/meshes/r_arm_grip_thumb.STL" />
            </geometry>
            <material name="">
                <color rgba="0.79216 0.81961 0.33333 1" />
            </material>
        </visual>
        <collision>
            <origin xyz="0 0 0" rpy="0 0 0" />
            <geometry>
                <mesh filename="package://transcent_urdf/meshes/r_arm_grip_thumb.STL" />
            </geometry>
        </collision>
    </link>

  <!-- Joint 8 -->
    <joint name="r_arm_grip_thumb_joint" type="revolute">
        <origin xyz="-0.03209 -0.046313 0.061228" rpy="-1.5708 -0.79395 3.0953" />
        <parent link="r_arm_wr_p" />
        <child link="r_arm_grip_thumb" />
        <axis xyz="0 0 1" />
        <limit lower="-3.14" upper="3.14" effort="3.7" velocity="6.28" />
        <dynamics damping="1.0" friction="0"/>
    </joint>


    <link name="r_arm_grip_index">
        <inertial>
            <origin xyz="0.021582 0.039055 -0.020254" rpy="0 0 0" />
            <mass value="0.037783" />
            <inertia ixx="1.0" ixy="0.0" ixz="0.0" iyy="1.0" iyz="0.0" izz="1.0" />
        </inertial>
        <visual>
            <origin xyz="0 0 0" rpy="0 0 0" />
            <geometry>
                <mesh filename="package://transcent_urdf/meshes/r_arm_grip_index.STL" />
            </geometry>
            <material name="">
                <color rgba="0.79216 0.81961 0.33333 1" />
            </material>
        </visual>
        <collision>
            <origin xyz="0 0 0" rpy="0 0 0" />
            <geometry>
                <mesh filename="package://transcent_urdf/meshes/r_arm_grip_index.STL" />
            </geometry>
        </collision>
    </link>

    <!-- Joint 9 -->
    <joint name="r_arm_grip_index_joint" type="revolute">
        <origin xyz="0.024624 -0.048943 0.088022" rpy="1.5708 -0.7854 -0.046338" />
        <parent link="r_arm_wr_p" />
        <child link="r_arm_grip_index" />
        <axis xyz="0 0 1" />
        <limit lower="-3.14" upper="3.14" effort="3.7" velocity="6.28" />
        <dynamics damping="1.0" friction="0"/>
    </joint>

    <link name="r_arm_grip_middle">
        <inertial>
            <origin xyz="0.032022 -0.0299 -0.02025" rpy="0 0 0" />
            <mass value="0.03778" />
            <inertia ixx="1.0" ixy="0.0" ixz="0.0" iyy="1.0" iyz="0.0" izz="1.0" />
        </inertial>
        <visual>
            <origin xyz="0 0 0" rpy="0 0 0" />
            <geometry>
                <mesh filename="package://transcent_urdf/meshes/r_arm_grip_middle.STL" />
            </geometry>
            <material name="">
                <color rgba="0.79216 0.81961 0.33333 1" />
            </material>
        </visual>
        <collision>
            <origin xyz="0 0 0" rpy="0 0 0" />
            <geometry>
                <mesh filename="package://transcent_urdf/meshes/r_arm_grip_middle.STL" />
            </geometry>
        </collision>
    </link>
    
    <joint name="r_arm_grip_middle_joint" type="revolute">
        <origin xyz="0.029001 0.045455 0.088022" rpy="-1.5708 -0.7854 -0.046338" />
        <parent link="r_arm_wr_p" />
        <child link="r_arm_grip_middle" />
        <axis xyz="0 0 1" />
        <limit lower="-3.14" upper="3.14" effort="3.7" velocity="6.28" />
        <dynamics damping="1.0" friction="0"/>
    </joint>
    <!--****************  Left Arm  ******************-->
    <link name="l_arm_sh_p1">
        <inertial>
            <origin xyz="0.43674 -0.027128 -0.25506" rpy="0 0 0" />
            <mass value="0.2" />
            <inertia ixx="1.0" ixy="0.0" ixz="0.0" iyy="1.0" iyz="0.0" izz="1.0" />
        </inertial>
        <visual>
            <origin xyz="0 0 0" rpy="0 0 0" />
            <geometry>
                <mesh filename="package://transcent_urdf/meshes/l_arm_sh_p1.STL" />
            </geometry>
            <material name="">
                <color rgba="0.19216 0.21961 0.2 1" />
            </material>
        </visual>
        <collision>
            <origin xyz="0 0 0" rpy="0 0 0" />
            <geometry>
                <mesh filename="package://transcent_urdf/meshes/l_arm_sh_p1.STL" />
            </geometry>
        </collision>
    </link>

    <joint name="l_arm_sh_p1_joint" type="revolute">
        <origin xyz="0 0.25321 0.0004722" rpy="0 1.5689 1.5708" />
        <parent link="base_link" />
        <child link="l_arm_sh_p1" />
        <axis xyz="0 0 1" />
        <limit lower="-3.14" upper="3.14" effort="130" velocity="3.14" />
        <dynamics damping="1.0" friction="0"/>
    </joint>
    <link name="l_arm_sh_r">
        <inertial>
            <origin xyz="0.0045886 -0.12991 -0.00049641" rpy="0 0 0" />
            <mass value="0.2" />
            <inertia ixx="1.0" ixy="0.0" ixz="0.0" iyy="1.0" iyz="0.0" izz="1.0" />
        </inertial>
        <visual>
            <origin xyz="0 0 0" rpy="0 0 0" />
            <geometry>
                <mesh filename="package://transcent_urdf/meshes/l_arm_sh_r.STL" />
            </geometry>
            <material name="">
                <color rgba="0.09216 0.81961 0.03333 1" />
            </material>
        </visual>
        <collision>
            <origin xyz="0 0 0" rpy="0 0 0" />
            <geometry>
                <mesh filename="package://transcent_urdf/meshes/l_arm_sh_r.STL" />
            </geometry>
        </collision>
    </link>
    <joint name="l_arm_sh_r_joint" type="revolute">
        <origin xyz="0 0 0" rpy="-1.5708 1.5708 0" />
        <parent link="l_arm_sh_p1" />
        <child link="l_arm_sh_r" />
        <axis xyz="0 0 1" />
        <limit lower="-3.14" upper="3.14" effort="130" velocity="3.14" />
        <dynamics damping="1.0" friction="0"/>
    </joint>
    <link name="l_arm_sh_p2">
        <inertial>
            <origin xyz="-1.3509E-16 -5.5511E-17 -0.05105" rpy="0 0 0" />
            <mass value="0.2" />
            <inertia ixx="1.0" ixy="0.0" ixz="0.0" iyy="1.0" iyz="0.0" izz="1.0" />
        </inertial>
        <visual>
            <origin xyz="0 0 0" rpy="0 0 0" />
            <geometry>
                <mesh filename="package://transcent_urdf/meshes/l_arm_sh_p2.STL" />
            </geometry>
            <material name="silver" />
        </visual>
        <collision>
            <origin xyz="0 0 0" rpy="0 0 0" />
            <geometry>
                <mesh filename="package://transcent_urdf/meshes/l_arm_sh_p2.STL" />
            </geometry>
        </collision>
    </link>
    <!-- JOINT3 -->
    <joint name="l_arm_sh_p2_joint" type="revolute">
        <origin xyz="0.0082954 -0.23485 -0.0005" rpy="0.01473 1.5708 -1.5208" />
        <parent link="l_arm_sh_r" />
        <child link="l_arm_sh_p2" />
        <axis xyz="0 0 1" />
        <limit lower="-3.14" upper="3.14" effort="130" velocity="3.14" />
        <dynamics damping="1.0" friction="0"/>
    </joint>
    <link name="l_arm_el_y">
        <inertial>
            <origin xyz="0.005053 0.21103 -0.24071" rpy="0 0 0" />
            <mass value="0.2" />
            <inertia ixx="1.0" ixy="0.0" ixz="0.0" iyy="1.0" iyz="0.0" izz="1.0" />
        </inertial>
        <visual>
            <origin xyz="0 0 0" rpy="0 0 0" />
            <geometry>
                <mesh filename="package://transcent_urdf/meshes/l_arm_el_y.STL" />
            </geometry>
            <material name="">
                <color rgba="0.79216 0.11961 0.13333 1" />
            </material>
        </visual>
        <collision>
            <origin xyz="0 0 0" rpy="0 0 0" />
            <geometry>
                <mesh filename="package://transcent_urdf/meshes/l_arm_el_y.STL" />
            </geometry>
        </collision>
    </link>
    <!-- JOINT4 -->
    <joint name="l_arm_el_y_joint" type="revolute">
        <origin xyz="0 0 0" rpy="1.5708 0.070191 -0.047606" />
        <parent link="l_arm_sh_p2" />
        <child link="l_arm_el_y" />
        <axis xyz="0 0 1" />
        <limit lower="-3.14" upper="3.14" effort="130" velocity="3.14" />
        <dynamics damping="1.0" friction="0"/>
    </joint>
    <link name="l_arm_wr_r">
        <inertial>
            <origin xyz="0.005053 0.24071 0.0026416" rpy="0 0 0" />
            <mass value="0.2" />
            <inertia ixx="1.0" ixy="0.0" ixz="0.0" iyy="1.0" iyz="0.0" izz="1.0" />
        </inertial>
        <visual>
            <origin xyz="0 0 0" rpy="0 0 0" />
            <geometry>
                <mesh filename="package://transcent_urdf/meshes/l_arm_wr_r.STL" />
            </geometry>
            <material name="grey" />
        </visual>
        <collision>
            <origin xyz="0 0 0" rpy="0 0 0" />
            <geometry>
                <mesh filename="package://transcent_urdf/meshes/l_arm_wr_r.STL" />
            </geometry>
        </collision>
    </link>
    <!-- JOINT5 -->
    <joint name="l_arm_wr_r_joint" type="revolute">
        <origin xyz="0 0.20839 0" rpy="-1.5708 0 0" />
        <parent link="l_arm_el_y" />
        <child link="l_arm_wr_r" />
        <axis xyz="0 0 1" />
        <limit lower="-3.14" upper="3.14" effort="100" velocity="3.14" />
        <dynamics damping="1.0" friction="0"/>
    </joint>
    <link name="l_arm_wr_y">
        <inertial>
            <origin xyz="-0.0085486 -0.0026416 0.24061" rpy="0 0 0" />
            <mass value="0.2" />
            <inertia ixx="1.0" ixy="0.0" ixz="0.0" iyy="1.0" iyz="0.0" izz="1.0" />
        </inertial>
        <visual>
            <origin xyz="0 0 0" rpy="0 0 0" />
            <geometry>
                <mesh filename="package://transcent_urdf/meshes/l_arm_wr_y.STL" />
            </geometry>
            <material name="">
                <color rgba="0.09216 0.81961 0.03333 1" />
            </material>
        </visual>
        <collision>
            <origin xyz="0 0 0" rpy="0 0 0" />
            <geometry>
                <mesh filename="package://transcent_urdf/meshes/l_arm_wr_y.STL" />
            </geometry>
        </collision>
    </link>
    <!-- JOINT6 -->
    <joint name="l_arm_wr_y_joint" type="revolute">
        <origin xyz="0 0 0" rpy="-1.5708 0 -0.056502" />
        <parent link="l_arm_wr_r" />
        <child link="l_arm_wr_y" />
        <axis xyz="0 0 1" />
        <limit lower="-3.14" upper="3.14" effort="100" velocity="3.14" />
        <dynamics damping="1.0" friction="0"/>
    </joint>
    <link name="l_arm_wr_p">
        <inertial>
            <origin xyz="-0.0038604 0.00024323 0.048771" rpy="0 0 0" />
            <mass value="0.2" />
            <inertia ixx="1.0" ixy="0.0" ixz="0.0" iyy="1.0" iyz="0.0" izz="1.0" />
        </inertial>
        <visual>
            <origin xyz="0 0 0" rpy="0 0 0" />
            <geometry>
                <mesh filename="package://transcent_urdf/meshes/l_arm_wr_p.STL" />
            </geometry>
            <material name="">
                <color rgba="0.79216 0.81961 0.33333 1" />
            </material>
        </visual>
        <collision>
            <origin xyz="0 0 0" rpy="0 0 0" />
            <geometry>
                <mesh filename="package://transcent_urdf/meshes/l_arm_wr_p.STL" />
            </geometry>
        </collision>
    </link>
    <!-- JOINT7 -->
    <joint name="l_arm_wr_p_joint" type="revolute">
        <origin xyz="-0.0023782 -0.10317 0" rpy="2.9333 -1.5708 -1.3855" />
        <parent link="l_arm_wr_y" />
        <child link="l_arm_wr_p" />
        <axis xyz="0 0 1" />
        <limit lower="-3.14" upper="3.14" effort="100" velocity="3.14" />
        <dynamics damping="1.0" friction="0"/>
    </joint>
    <link name="l_arm_grip_thumb">
        <inertial>
            <origin xyz="0.038624 -0.0062103 -0.020232" rpy="0 0 0" />
            <mass value="0.041233" />
            <inertia ixx="1.0" ixy="0.0" ixz="0.0" iyy="1.0" iyz="0.0" izz="1.0" />
        </inertial>
        <visual>
            <origin xyz="0 0 0" rpy="0 0 0" />
            <geometry>
                <mesh filename="package://transcent_urdf/meshes/l_arm_grip_thumb.STL" />
            </geometry>
            <material name="">
                <color rgba="0.79216 0.81961 0.33333 1" />
            </material>
        </visual>
        <collision>
            <origin xyz="0 0 0" rpy="0 0 0" />
            <geometry>
                <mesh filename="package://transcent_urdf/meshes/l_arm_grip_thumb.STL" />
            </geometry>
        </collision>
    </link>
    <!-- JOINT8 -->    
    <joint name="l_arm_grip_thumb_joint" type="revolute">
        <origin xyz="0.013423 -0.052958 0.061228" rpy="1.5708 -0.79395 -0.33001" />
        <parent link="l_arm_wr_p" />
        <child link="l_arm_grip_thumb" />
        <axis xyz="0 0 1" />
        <limit lower="-3.14" upper="3.14" effort="3.7" velocity="6.28" />
        <dynamics damping="1.0" friction="0"/>
    </joint>
    <link name="l_arm_grip_index">
        <inertial>
            <origin xyz="0.031429 -0.031684 -0.020246" rpy="0 0 0" />
            <mass value="0.03778" />
            <inertia ixx="1.0" ixy="0.0" ixz="0.0" iyy="1.0" iyz="0.0" izz="1.0" />
        </inertial>
        <visual>
            <origin xyz="0 0 0" rpy="0 0 0" />
            <geometry>
                <mesh filename="package://transcent_urdf/meshes/l_arm_grip_index.STL" />
            </geometry>
            <material name="">
                <color rgba="0.79216 0.81961 0.33333 1" />
            </material>
        </visual>
        <collision>
            <origin xyz="0 0 0" rpy="0 0 0" />
            <geometry>
                <mesh filename="package://transcent_urdf/meshes/l_arm_grip_index.STL" />
            </geometry>
        </collision>
    </link>
    <joint name="l_arm_grip_index_joint" type="revolute">
        <origin xyz="-0.040612 -0.035505 0.088022" rpy="-1.5708 -0.7854 2.8116" />
        <parent link="l_arm_wr_p" />
        <child link="l_arm_grip_index" />
        <axis xyz="0 0 1" />
        <limit lower="-3.14" upper="3.14" effort="3.7" velocity="6.28" />
        <dynamics damping="1.0" friction="0"/>
    </joint>
    <link name="l_arm_grip_middle">
        <inertial>
            <origin xyz="0.033722 0.027968 -0.02025" rpy="0 0 0" />
            <mass value="0.037779" />
            <inertia ixx="1.0" ixy="0.0" ixz="0.0" iyy="1.0" iyz="0.0" izz="1.0" />
        </inertial>
        <visual>
            <origin xyz="0 0 0" rpy="0 0 0" />
            <geometry>
                <mesh filename="package://transcent_urdf/meshes/l_arm_grip_middle.STL" />
            </geometry>
            <material name="">
                <color rgba="0.79216 0.81961 0.33333 1" />
            </material>
        </visual>
        <collision>
            <origin xyz="0 0 0" rpy="0 0 0" />
            <geometry>
                <mesh filename="package://transcent_urdf/meshes/l_arm_grip_middle.STL" />
            </geometry>
        </collision>
    </link>
    <joint name="l_arm_grip_middle_joint" type="revolute">
        <origin xyz="-0.0099887 0.053895 0.088022" rpy="1.5708 -0.7854 2.8116" />
        <parent link="l_arm_wr_p" />
        <child link="l_arm_grip_middle" />
        <axis xyz="0 0 1" />
        <limit lower="-3.14" upper="3.14" effort="3.7" velocity="6.28" />
        <dynamics damping="1.0" friction="0"/>
    </joint>


<!--****************  transmission  ******************-->
<!--**********************************************-->    
    <transmission name="trans_r_arm_sh_p1">
        <type>transmission_interface/SimpleTransmission</type>
        <joint name="r_arm_sh_p1_joint">
            <hardwareInterface>hardware_interface/EffortJointInterface</hardwareInterface>
        </joint>
        <actuator name="r_arm_sh_p1_motor">
            <hardwareInterface>hardware_interface/EffortJointInterface</hardwareInterface>
            <mechanicalReduction>1</mechanicalReduction>
        </actuator>
    </transmission>
    <transmission name="trans_r_arm_sh_r">
        <type>transmission_interface/SimpleTransmission</type>
        <joint name="r_arm_sh_r_joint">
            <hardwareInterface>hardware_interface/EffortJointInterface</hardwareInterface>
        </joint>
        <actuator name="r_arm_sh_r_motor">
            <hardwareInterface>hardware_interface/EffortJointInterface</hardwareInterface>
            <mechanicalReduction>1</mechanicalReduction>
        </actuator>
    </transmission>
    <transmission name="trans_r_arm_sh_p2">
        <type>transmission_interface/SimpleTransmission</type>
        <joint name="r_arm_sh_p2_joint">
            <hardwareInterface>hardware_interface/EffortJointInterface</hardwareInterface>
        </joint>
        <actuator name="r_arm_sh_p2_motor">
            <hardwareInterface>hardware_interface/EffortJointInterface</hardwareInterface>
            <mechanicalReduction>1</mechanicalReduction>
        </actuator>
    </transmission>
    <transmission name="trans_r_arm_el_y">
        <type>transmission_interface/SimpleTransmission</type>
        <joint name="r_arm_el_y_joint">
            <hardwareInterface>hardware_interface/EffortJointInterface</hardwareInterface>
        </joint>
        <actuator name="r_arm_el_y_motor">
            <hardwareInterface>hardware_interface/EffortJointInterface</hardwareInterface>
            <mechanicalReduction>1</mechanicalReduction>
        </actuator>
    </transmission>
    <transmission name="trans_r_arm_wr_r">
        <type>transmission_interface/SimpleTransmission</type>
        <joint name="r_arm_wr_r_joint">
            <hardwareInterface>hardware_interface/EffortJointInterface</hardwareInterface>
        </joint>
        <actuator name="r_arm_wr_r_motor">
            <hardwareInterface>hardware_interface/EffortJointInterface</hardwareInterface>
            <mechanicalReduction>1</mechanicalReduction>
        </actuator>
    </transmission>
    <transmission name="trans_r_arm_wr_y">
        <type>transmission_interface/SimpleTransmission</type>
        <joint name="r_arm_wr_y_joint">
            <hardwareInterface>hardware_interface/EffortJointInterface</hardwareInterface>
        </joint>
        <actuator name="r_arm_wr_y_motor">
            <hardwareInterface>hardware_interface/EffortJointInterface</hardwareInterface>
            <mechanicalReduction>1</mechanicalReduction>
        </actuator>
    </transmission>
    <transmission name="trans_r_arm_wr_p">
        <type>transmission_interface/SimpleTransmission</type>
        <joint name="r_arm_wr_p_joint">
            <hardwareInterface>hardware_interface/EffortJointInterface</hardwareInterface>
        </joint>
        <actuator name="r_arm_wr_p_motor">
            <hardwareInterface>hardware_interface/EffortJointInterface</hardwareInterface>
            <mechanicalReduction>1</mechanicalReduction>
        </actuator>
    </transmission>
    <transmission name="trans_r_arm_grip_thumb">
        <type>transmission_interface/SimpleTransmission</type>
        <joint name="r_arm_grip_thumb_joint">
            <hardwareInterface>hardware_interface/EffortJointInterface</hardwareInterface>
        </joint>
        <actuator name="r_arm_grip_thumb_motor">
            <hardwareInterface>hardware_interface/EffortJointInterface</hardwareInterface>
            <mechanicalReduction>1</mechanicalReduction>
        </actuator>
    </transmission>
    <transmission name="trans_r_arm_grip_index">
        <type>transmission_interface/SimpleTransmission</type>
        <joint name="r_arm_grip_index_joint">
            <hardwareInterface>hardware_interface/EffortJointInterface</hardwareInterface>
        </joint>
        <actuator name="r_arm_grip_index_motor">
            <hardwareInterface>hardware_interface/EffortJointInterface</hardwareInterface>
            <mechanicalReduction>1</mechanicalReduction>
        </actuator>
    </transmission>
    <transmission name="trans_r_arm_grip_middle">
        <type>transmission_interface/SimpleTransmission</type>
        <joint name="r_arm_grip_middle_joint">
            <hardwareInterface>hardware_interface/EffortJointInterface</hardwareInterface>
        </joint>
        <actuator name="r_arm_grip_middle_motor">
            <hardwareInterface>hardware_interface/EffortJointInterface</hardwareInterface>
            <mechanicalReduction>1</mechanicalReduction>
        </actuator>
    </transmission>
    <transmission name="trans_l_arm_sh_p1">
        <type>transmission_interface/SimpleTransmission</type>
        <joint name="l_arm_sh_p1_joint">
            <hardwareInterface>hardware_interface/EffortJointInterface</hardwareInterface>
        </joint>
        <actuator name="l_arm_sh_p1_motor">
            <hardwareInterface>hardware_interface/EffortJointInterface</hardwareInterface>
            <mechanicalReduction>1</mechanicalReduction>
        </actuator>
    </transmission>
    <transmission name="trans_l_arm_sh_r">
        <type>transmission_interface/SimpleTransmission</type>
        <joint name="l_arm_sh_r_joint">
            <hardwareInterface>hardware_interface/EffortJointInterface</hardwareInterface>
        </joint>
        <actuator name="l_arm_sh_r_motor">
            <hardwareInterface>hardware_interface/EffortJointInterface</hardwareInterface>
            <mechanicalReduction>1</mechanicalReduction>
        </actuator>
    </transmission>
    <transmission name="trans_l_arm_sh_p2">
        <type>transmission_interface/SimpleTransmission</type>
        <joint name="l_arm_sh_p2_joint">
            <hardwareInterface>hardware_interface/EffortJointInterface</hardwareInterface>
        </joint>
        <actuator name="l_arm_sh_p2_motor">
            <hardwareInterface>hardware_interface/EffortJointInterface</hardwareInterface>
            <mechanicalReduction>1</mechanicalReduction>
        </actuator>
    </transmission>
    <transmission name="trans_l_arm_el_y">
        <type>transmission_interface/SimpleTransmission</type>
        <joint name="l_arm_el_y_joint">
            <hardwareInterface>hardware_interface/EffortJointInterface</hardwareInterface>
        </joint>
        <actuator name="l_arm_el_y_motor">
            <hardwareInterface>hardware_interface/EffortJointInterface</hardwareInterface>
            <mechanicalReduction>1</mechanicalReduction>
        </actuator>
    </transmission>
    <transmission name="trans_l_arm_wr_r">
        <type>transmission_interface/SimpleTransmission</type>
        <joint name="l_arm_wr_r_joint">
            <hardwareInterface>hardware_interface/EffortJointInterface</hardwareInterface>
        </joint>
        <actuator name="l_arm_wr_r_motor">
            <hardwareInterface>hardware_interface/EffortJointInterface</hardwareInterface>
            <mechanicalReduction>1</mechanicalReduction>
        </actuator>
    </transmission>
    <transmission name="trans_l_arm_wr_y">
        <type>transmission_interface/SimpleTransmission</type>
        <joint name="l_arm_wr_y_joint">
            <hardwareInterface>hardware_interface/EffortJointInterface</hardwareInterface>
        </joint>
        <actuator name="l_arm_wr_y_motor">
            <hardwareInterface>hardware_interface/EffortJointInterface</hardwareInterface>
            <mechanicalReduction>1</mechanicalReduction>
        </actuator>
    </transmission>
    <transmission name="trans_l_arm_wr_p">
        <type>transmission_interface/SimpleTransmission</type>
        <joint name="l_arm_wr_p_joint">
            <hardwareInterface>hardware_interface/EffortJointInterface</hardwareInterface>
        </joint>
        <actuator name="l_arm_wr_p_motor">
            <hardwareInterface>hardware_interface/EffortJointInterface</hardwareInterface>
            <mechanicalReduction>1</mechanicalReduction>
        </actuator>
    </transmission>
    <transmission name="trans_l_arm_grip_thumb">
        <type>transmission_interface/SimpleTransmission</type>
        <joint name="l_arm_grip_thumb_joint">
            <hardwareInterface>hardware_interface/EffortJointInterface</hardwareInterface>
        </joint>
        <actuator name="l_arm_grip_thumb_motor">
            <hardwareInterface>hardware_interface/EffortJointInterface</hardwareInterface>
            <mechanicalReduction>1</mechanicalReduction>
        </actuator>
    </transmission>
    <transmission name="trans_l_arm_grip_index">
        <type>transmission_interface/SimpleTransmission</type>
        <joint name="l_arm_grip_index_joint">
            <hardwareInterface>hardware_interface/EffortJointInterface</hardwareInterface>
        </joint>
        <actuator name="l_arm_grip_index_motor">
            <hardwareInterface>hardware_interface/EffortJointInterface</hardwareInterface>
            <mechanicalReduction>1</mechanicalReduction>
        </actuator>
    </transmission>
    <transmission name="trans_l_arm_grip_middle">
        <type>transmission_interface/SimpleTransmission</type>
        <joint name="l_arm_grip_middle_joint">
            <hardwareInterface>hardware_interface/EffortJointInterface</hardwareInterface>
        </joint>
        <actuator name="l_arm_grip_middle_motor">
            <hardwareInterface>hardware_interface/EffortJointInterface</hardwareInterface>
            <mechanicalReduction>1</mechanicalReduction>
        </actuator>
    </transmission>

    <gazebo>
        <plugin name="gazebo_ros_control" filename="libgazebo_ros_control.so">
            <robotNamespace>/</robotNamespace>
        </plugin>
    </gazebo>
</robot>

